2025-08-13 12:36:22,677 - glyphmind.error - ERROR - Failed to initialize OpenAI model | Exception: name 'log_warning' is not defined
Traceback (most recent call last):
  File "C:\Users\Public\ALL WORKING MODELS HERE\NEW MODEL FOR DEV\GLYPHMIND\glyphmind\core\ai_engine.py", line 160, in initialize
    log_warning("OpenAI API key not configured")
    ^^^^^^^^^^^
NameError: name 'log_warning' is not defined
2025-08-13 12:36:40,677 - glyphmind.error - ERROR - Failed to initialize OpenAI model | Exception: name 'log_warning' is not defined
Traceback (most recent call last):
  File "C:\Users\Public\ALL WORKING MODELS HERE\NEW MODEL FOR DEV\GLYPHMIND\glyphmind\core\ai_engine.py", line 160, in initialize
    log_warning("OpenAI API key not configured")
    ^^^^^^^^^^^
NameError: name 'log_warning' is not defined
2025-08-13 12:44:24,638 - glyphmind.error - ERROR - Failed to initialize OpenAI model | Exception: name 'log_warning' is not defined
Traceback (most recent call last):
  File "C:\Users\Public\ALL WORKING MODELS HERE\NEW MODEL FOR DEV\GLYPHMIND\glyphmind\core\ai_engine.py", line 160, in initialize
    log_warning("OpenAI API key not configured")
    ^^^^^^^^^^^
NameError: name 'log_warning' is not defined
2025-08-13 12:45:00,453 - glyphmind.error - ERROR - Request routing failed | Data: {"request_id": "7e476342-232f-4c84-b52b-4d6488959ba7", "request_type": "status"} | Exception: No route found for request type: RequestType.STATUS
Traceback (most recent call last):
  File "C:\Users\Public\ALL WORKING MODELS HERE\NEW MODEL FOR DEV\GLYPHMIND\glyphmind\router\request_router.py", line 318, in route_request
    raise ValueError(f"No route found for request type: {context.request_type}")
ValueError: No route found for request type: RequestType.STATUS
2025-08-13 12:45:00,454 - glyphmind.error - ERROR - Status endpoint error | Exception: No route found for request type: RequestType.STATUS
Traceback (most recent call last):
  File "C:\Users\Public\ALL WORKING MODELS HERE\NEW MODEL FOR DEV\GLYPHMIND\glyphmind\server\app.py", line 361, in status_endpoint
    response = await request_router.route_request(context)
               ^^^^^^^^^^^^^^^^^^^^^^^^^^^^^^^^^^^^^^^^^^^
  File "C:\Users\Public\ALL WORKING MODELS HERE\NEW MODEL FOR DEV\GLYPHMIND\glyphmind\router\request_router.py", line 318, in route_request
    raise ValueError(f"No route found for request type: {context.request_type}")
ValueError: No route found for request type: RequestType.STATUS
2025-08-13 12:45:04,604 - glyphmind.error - ERROR - Request routing failed | Data: {"request_id": "2f492aa9-1f94-4e94-b4bb-3def0ea982ca", "request_type": "chat"} | Exception: No route found for request type: RequestType.CHAT
Traceback (most recent call last):
  File "C:\Users\Public\ALL WORKING MODELS HERE\NEW MODEL FOR DEV\GLYPHMIND\glyphmind\router\request_router.py", line 318, in route_request
    raise ValueError(f"No route found for request type: {context.request_type}")
ValueError: No route found for request type: RequestType.CHAT
2025-08-13 12:45:04,605 - glyphmind.error - ERROR - Chat endpoint error | Exception: No route found for request type: RequestType.CHAT
Traceback (most recent call last):
  File "C:\Users\Public\ALL WORKING MODELS HERE\NEW MODEL FOR DEV\GLYPHMIND\glyphmind\server\app.py", line 315, in chat_endpoint
    response = await request_router.route_request(context)
               ^^^^^^^^^^^^^^^^^^^^^^^^^^^^^^^^^^^^^^^^^^^
  File "C:\Users\Public\ALL WORKING MODELS HERE\NEW MODEL FOR DEV\GLYPHMIND\glyphmind\router\request_router.py", line 318, in route_request
    raise ValueError(f"No route found for request type: {context.request_type}")
ValueError: No route found for request type: RequestType.CHAT
2025-08-13 12:45:09,022 - glyphmind.error - ERROR - Request routing failed | Data: {"request_id": "cfed3cbd-9f12-46df-b388-573f7b70e6fa", "request_type": "chat"} | Exception: No route found for request type: RequestType.CHAT
Traceback (most recent call last):
  File "C:\Users\Public\ALL WORKING MODELS HERE\NEW MODEL FOR DEV\GLYPHMIND\glyphmind\router\request_router.py", line 318, in route_request
    raise ValueError(f"No route found for request type: {context.request_type}")
ValueError: No route found for request type: RequestType.CHAT
2025-08-13 12:45:09,023 - glyphmind.error - ERROR - Chat endpoint error | Exception: No route found for request type: RequestType.CHAT
Traceback (most recent call last):
  File "C:\Users\Public\ALL WORKING MODELS HERE\NEW MODEL FOR DEV\GLYPHMIND\glyphmind\server\app.py", line 315, in chat_endpoint
    response = await request_router.route_request(context)
               ^^^^^^^^^^^^^^^^^^^^^^^^^^^^^^^^^^^^^^^^^^^
  File "C:\Users\Public\ALL WORKING MODELS HERE\NEW MODEL FOR DEV\GLYPHMIND\glyphmind\router\request_router.py", line 318, in route_request
    raise ValueError(f"No route found for request type: {context.request_type}")
ValueError: No route found for request type: RequestType.CHAT
2025-08-13 12:45:54,979 - glyphmind.error - ERROR - Failed to initialize OpenAI model | Exception: name 'log_warning' is not defined
Traceback (most recent call last):
  File "C:\Users\Public\ALL WORKING MODELS HERE\NEW MODEL FOR DEV\GLYPHMIND\glyphmind\core\ai_engine.py", line 160, in initialize
    log_warning("OpenAI API key not configured")
    ^^^^^^^^^^^
NameError: name 'log_warning' is not defined
2025-08-13 12:46:26,605 - glyphmind.error - ERROR - Request routing failed | Data: {"request_id": "dde53e3c-f3e9-4c8d-b43e-d028c606bb75", "request_type": "status"} | Exception: No route found for request type: RequestType.STATUS
Traceback (most recent call last):
  File "C:\Users\Public\ALL WORKING MODELS HERE\NEW MODEL FOR DEV\GLYPHMIND\glyphmind\router\request_router.py", line 318, in route_request
    raise ValueError(f"No route found for request type: {context.request_type}")
ValueError: No route found for request type: RequestType.STATUS
2025-08-13 12:46:26,606 - glyphmind.error - ERROR - Status endpoint error | Exception: No route found for request type: RequestType.STATUS
Traceback (most recent call last):
  File "C:\Users\Public\ALL WORKING MODELS HERE\NEW MODEL FOR DEV\GLYPHMIND\glyphmind\server\app.py", line 361, in status_endpoint
    response = await request_router.route_request(context)
               ^^^^^^^^^^^^^^^^^^^^^^^^^^^^^^^^^^^^^^^^^^^
  File "C:\Users\Public\ALL WORKING MODELS HERE\NEW MODEL FOR DEV\GLYPHMIND\glyphmind\router\request_router.py", line 318, in route_request
    raise ValueError(f"No route found for request type: {context.request_type}")
ValueError: No route found for request type: RequestType.STATUS
2025-08-13 12:46:33,090 - glyphmind.error - ERROR - Request routing failed | Data: {"request_id": "396953cc-d646-42f8-9f9a-4d1856328214", "request_type": "status"} | Exception: No route found for request type: RequestType.STATUS
Traceback (most recent call last):
  File "C:\Users\Public\ALL WORKING MODELS HERE\NEW MODEL FOR DEV\GLYPHMIND\glyphmind\router\request_router.py", line 318, in route_request
    raise ValueError(f"No route found for request type: {context.request_type}")
ValueError: No route found for request type: RequestType.STATUS
2025-08-13 12:46:33,091 - glyphmind.error - ERROR - Status endpoint error | Exception: No route found for request type: RequestType.STATUS
Traceback (most recent call last):
  File "C:\Users\Public\ALL WORKING MODELS HERE\NEW MODEL FOR DEV\GLYPHMIND\glyphmind\server\app.py", line 361, in status_endpoint
    response = await request_router.route_request(context)
               ^^^^^^^^^^^^^^^^^^^^^^^^^^^^^^^^^^^^^^^^^^^
  File "C:\Users\Public\ALL WORKING MODELS HERE\NEW MODEL FOR DEV\GLYPHMIND\glyphmind\router\request_router.py", line 318, in route_request
    raise ValueError(f"No route found for request type: {context.request_type}")
ValueError: No route found for request type: RequestType.STATUS
2025-08-13 12:46:38,419 - glyphmind.error - ERROR - Request routing failed | Data: {"request_id": "d625f377-3c3b-4480-8d35-fb6edb882442", "request_type": "chat"} | Exception: No route found for request type: RequestType.CHAT
Traceback (most recent call last):
  File "C:\Users\Public\ALL WORKING MODELS HERE\NEW MODEL FOR DEV\GLYPHMIND\glyphmind\router\request_router.py", line 318, in route_request
    raise ValueError(f"No route found for request type: {context.request_type}")
ValueError: No route found for request type: RequestType.CHAT
2025-08-13 12:46:38,420 - glyphmind.error - ERROR - Chat endpoint error | Exception: No route found for request type: RequestType.CHAT
Traceback (most recent call last):
  File "C:\Users\Public\ALL WORKING MODELS HERE\NEW MODEL FOR DEV\GLYPHMIND\glyphmind\server\app.py", line 315, in chat_endpoint
    response = await request_router.route_request(context)
               ^^^^^^^^^^^^^^^^^^^^^^^^^^^^^^^^^^^^^^^^^^^
  File "C:\Users\Public\ALL WORKING MODELS HERE\NEW MODEL FOR DEV\GLYPHMIND\glyphmind\router\request_router.py", line 318, in route_request
    raise ValueError(f"No route found for request type: {context.request_type}")
ValueError: No route found for request type: RequestType.CHAT
2025-08-13 12:46:47,413 - glyphmind.error - ERROR - Request routing failed | Data: {"request_id": "33f72241-b6f6-45f7-98c5-32ac24840ba8", "request_type": "status"} | Exception: No route found for request type: RequestType.STATUS
Traceback (most recent call last):
  File "C:\Users\Public\ALL WORKING MODELS HERE\NEW MODEL FOR DEV\GLYPHMIND\glyphmind\router\request_router.py", line 318, in route_request
    raise ValueError(f"No route found for request type: {context.request_type}")
ValueError: No route found for request type: RequestType.STATUS
2025-08-13 12:46:47,413 - glyphmind.error - ERROR - Status endpoint error | Exception: No route found for request type: RequestType.STATUS
Traceback (most recent call last):
  File "C:\Users\Public\ALL WORKING MODELS HERE\NEW MODEL FOR DEV\GLYPHMIND\glyphmind\server\app.py", line 361, in status_endpoint
    response = await request_router.route_request(context)
               ^^^^^^^^^^^^^^^^^^^^^^^^^^^^^^^^^^^^^^^^^^^
  File "C:\Users\Public\ALL WORKING MODELS HERE\NEW MODEL FOR DEV\GLYPHMIND\glyphmind\router\request_router.py", line 318, in route_request
    raise ValueError(f"No route found for request type: {context.request_type}")
ValueError: No route found for request type: RequestType.STATUS
2025-08-13 12:46:52,111 - glyphmind.error - ERROR - Request routing failed | Data: {"request_id": "93d79d62-3ffb-483c-bfa1-b8c5e5694f66", "request_type": "chat"} | Exception: No route found for request type: RequestType.CHAT
Traceback (most recent call last):
  File "C:\Users\Public\ALL WORKING MODELS HERE\NEW MODEL FOR DEV\GLYPHMIND\glyphmind\router\request_router.py", line 318, in route_request
    raise ValueError(f"No route found for request type: {context.request_type}")
ValueError: No route found for request type: RequestType.CHAT
2025-08-13 12:46:52,111 - glyphmind.error - ERROR - Chat endpoint error | Exception: No route found for request type: RequestType.CHAT
Traceback (most recent call last):
  File "C:\Users\Public\ALL WORKING MODELS HERE\NEW MODEL FOR DEV\GLYPHMIND\glyphmind\server\app.py", line 315, in chat_endpoint
    response = await request_router.route_request(context)
               ^^^^^^^^^^^^^^^^^^^^^^^^^^^^^^^^^^^^^^^^^^^
  File "C:\Users\Public\ALL WORKING MODELS HERE\NEW MODEL FOR DEV\GLYPHMIND\glyphmind\router\request_router.py", line 318, in route_request
    raise ValueError(f"No route found for request type: {context.request_type}")
ValueError: No route found for request type: RequestType.CHAT
2025-08-13 12:49:16,983 - glyphmind.error - ERROR - Failed to initialize OpenAI model | Exception: name 'log_warning' is not defined
Traceback (most recent call last):
  File "C:\Users\Public\ALL WORKING MODELS HERE\NEW MODEL FOR DEV\GLYPHMIND\glyphmind\core\ai_engine.py", line 160, in initialize
    log_warning("OpenAI API key not configured")
    ^^^^^^^^^^^
NameError: name 'log_warning' is not defined
2025-08-13 12:49:30,377 - glyphmind.error - ERROR - Failed to initialize OpenAI model | Exception: name 'log_warning' is not defined
Traceback (most recent call last):
  File "C:\Users\Public\ALL WORKING MODELS HERE\NEW MODEL FOR DEV\GLYPHMIND\glyphmind\core\ai_engine.py", line 160, in initialize
    log_warning("OpenAI API key not configured")
    ^^^^^^^^^^^
NameError: name 'log_warning' is not defined
2025-08-13 12:49:59,062 - glyphmind.error - ERROR - Failed to initialize OpenAI model | Exception: name 'log_warning' is not defined
Traceback (most recent call last):
  File "C:\Users\Public\ALL WORKING MODELS HERE\NEW MODEL FOR DEV\GLYPHMIND\glyphmind\core\ai_engine.py", line 160, in initialize
    log_warning("OpenAI API key not configured")
    ^^^^^^^^^^^
NameError: name 'log_warning' is not defined
2025-08-13 12:50:14,185 - glyphmind.error - ERROR - Failed to initialize OpenAI model | Exception: name 'log_warning' is not defined
Traceback (most recent call last):
  File "C:\Users\Public\ALL WORKING MODELS HERE\NEW MODEL FOR DEV\GLYPHMIND\glyphmind\core\ai_engine.py", line 160, in initialize
    log_warning("OpenAI API key not configured")
    ^^^^^^^^^^^
NameError: name 'log_warning' is not defined
2025-08-13 12:50:23,450 - glyphmind.error - ERROR - Failed to initialize OpenAI model | Exception: name 'log_warning' is not defined
Traceback (most recent call last):
  File "C:\Users\Public\ALL WORKING MODELS HERE\NEW MODEL FOR DEV\GLYPHMIND\glyphmind\core\ai_engine.py", line 160, in initialize
    log_warning("OpenAI API key not configured")
    ^^^^^^^^^^^
NameError: name 'log_warning' is not defined
2025-08-13 12:50:35,037 - glyphmind.error - ERROR - Failed to initialize OpenAI model | Exception: name 'log_warning' is not defined
Traceback (most recent call last):
  File "C:\Users\Public\ALL WORKING MODELS HERE\NEW MODEL FOR DEV\GLYPHMIND\glyphmind\core\ai_engine.py", line 160, in initialize
    log_warning("OpenAI API key not configured")
    ^^^^^^^^^^^
NameError: name 'log_warning' is not defined
2025-08-13 12:50:45,182 - glyphmind.error - ERROR - Failed to initialize OpenAI model | Exception: name 'log_warning' is not defined
Traceback (most recent call last):
  File "C:\Users\Public\ALL WORKING MODELS HERE\NEW MODEL FOR DEV\GLYPHMIND\glyphmind\core\ai_engine.py", line 160, in initialize
    log_warning("OpenAI API key not configured")
    ^^^^^^^^^^^
NameError: name 'log_warning' is not defined
2025-08-13 12:50:58,777 - glyphmind.error - ERROR - Failed to initialize OpenAI model | Exception: name 'log_warning' is not defined
Traceback (most recent call last):
  File "C:\Users\Public\ALL WORKING MODELS HERE\NEW MODEL FOR DEV\GLYPHMIND\glyphmind\core\ai_engine.py", line 160, in initialize
    log_warning("OpenAI API key not configured")
    ^^^^^^^^^^^
NameError: name 'log_warning' is not defined
2025-08-13 12:51:06,438 - glyphmind.error - ERROR - Failed to initialize OpenAI model | Exception: name 'log_warning' is not defined
Traceback (most recent call last):
  File "C:\Users\Public\ALL WORKING MODELS HERE\NEW MODEL FOR DEV\GLYPHMIND\glyphmind\core\ai_engine.py", line 160, in initialize
    log_warning("OpenAI API key not configured")
    ^^^^^^^^^^^
NameError: name 'log_warning' is not defined
2025-08-13 12:51:14,805 - glyphmind.error - ERROR - Failed to initialize OpenAI model | Exception: name 'log_warning' is not defined
Traceback (most recent call last):
  File "C:\Users\Public\ALL WORKING MODELS HERE\NEW MODEL FOR DEV\GLYPHMIND\glyphmind\core\ai_engine.py", line 160, in initialize
    log_warning("OpenAI API key not configured")
    ^^^^^^^^^^^
NameError: name 'log_warning' is not defined
2025-08-13 12:51:16,135 - glyphmind.error - ERROR - Reddit API error: 429
2025-08-13 12:51:16,159 - glyphmind.error - ERROR - Reddit API error: 429
2025-08-13 12:51:16,160 - glyphmind.error - ERROR - Reddit API error: 429
2025-08-13 12:51:17,156 - glyphmind.error - ERROR - Reddit API error: 429
2025-08-13 12:51:18,246 - glyphmind.error - ERROR - Reddit API error: 429
2025-08-13 12:51:18,247 - glyphmind.error - ERROR - Reddit API error: 429
2025-08-13 12:51:18,749 - glyphmind.error - ERROR - Reddit API error: 429
2025-08-13 12:51:19,173 - glyphmind.error - ERROR - Reddit API error: 429
2025-08-13 12:51:20,162 - glyphmind.error - ERROR - Reddit API error: 429
2025-08-13 12:51:20,174 - glyphmind.error - ERROR - Reddit API error: 429
2025-08-13 12:51:20,192 - glyphmind.error - ERROR - Reddit API error: 429
2025-08-13 12:51:21,198 - glyphmind.error - ERROR - Reddit API error: 429
2025-08-13 12:51:22,205 - glyphmind.error - ERROR - Reddit API error: 429
2025-08-13 12:51:22,207 - glyphmind.error - ERROR - Reddit API error: 429
2025-08-13 12:51:49,936 - glyphmind.error - ERROR - Failed to initialize OpenAI model | Exception: name 'log_warning' is not defined
Traceback (most recent call last):
  File "C:\Users\Public\ALL WORKING MODELS HERE\NEW MODEL FOR DEV\GLYPHMIND\glyphmind\core\ai_engine.py", line 160, in initialize
    log_warning("OpenAI API key not configured")
    ^^^^^^^^^^^
NameError: name 'log_warning' is not defined
2025-08-13 12:51:50,837 - glyphmind.error - ERROR - Reddit API error: 429
2025-08-13 12:51:51,347 - glyphmind.error - ERROR - Reddit API error: 429
2025-08-13 12:51:51,348 - glyphmind.error - ERROR - Reddit API error: 429
2025-08-13 12:51:51,509 - glyphmind.error - ERROR - Reddit API error: 429
2025-08-13 12:51:52,337 - glyphmind.error - ERROR - Reddit API error: 429
2025-08-13 12:51:53,358 - glyphmind.error - ERROR - Reddit API error: 429
2025-08-13 12:51:53,361 - glyphmind.error - ERROR - Reddit API error: 429
2025-08-13 12:51:53,361 - glyphmind.error - ERROR - Reddit API error: 429
2025-08-13 12:51:54,366 - glyphmind.error - ERROR - Reddit API error: 429
2025-08-13 12:51:55,306 - glyphmind.error - ERROR - Reddit API error: 429
2025-08-13 12:51:55,307 - glyphmind.error - ERROR - Reddit API error: 429
2025-08-13 12:51:55,311 - glyphmind.error - ERROR - Reddit API error: 429
2025-08-13 12:51:56,424 - glyphmind.error - ERROR - Reddit API error: 429
2025-08-13 12:51:57,323 - glyphmind.error - ERROR - Reddit API error: 429
2025-08-13 12:51:57,345 - glyphmind.error - ERROR - Reddit API error: 429
2025-08-13 12:52:01,793 - glyphmind.error - ERROR - Request routing failed | Data: {"request_id": "859bc9de-a703-4be3-a344-91c8cf3da59a", "request_type": "status"} | Exception: No route found for request type: RequestType.STATUS
Traceback (most recent call last):
  File "C:\Users\Public\ALL WORKING MODELS HERE\NEW MODEL FOR DEV\GLYPHMIND\glyphmind\router\request_router.py", line 318, in route_request
    raise ValueError(f"No route found for request type: {context.request_type}")
ValueError: No route found for request type: RequestType.STATUS
2025-08-13 12:52:01,794 - glyphmind.error - ERROR - Router error, falling back to direct handler: No route found for request type: RequestType.STATUS
2025-08-13 12:52:11,364 - glyphmind.error - ERROR - Request routing failed | Data: {"request_id": "bad0124c-2d30-4f11-91f5-fd104d86c259", "request_type": "chat"} | Exception: No route found for request type: RequestType.CHAT
Traceback (most recent call last):
  File "C:\Users\Public\ALL WORKING MODELS HERE\NEW MODEL FOR DEV\GLYPHMIND\glyphmind\router\request_router.py", line 318, in route_request
    raise ValueError(f"No route found for request type: {context.request_type}")
ValueError: No route found for request type: RequestType.CHAT
2025-08-13 12:52:11,365 - glyphmind.error - ERROR - Router error, falling back to direct handler: No route found for request type: RequestType.CHAT
2025-08-13 12:52:59,105 - glyphmind.error - ERROR - Failed to initialize OpenAI model | Exception: name 'log_warning' is not defined
Traceback (most recent call last):
  File "C:\Users\Public\ALL WORKING MODELS HERE\NEW MODEL FOR DEV\GLYPHMIND\glyphmind\core\ai_engine.py", line 160, in initialize
    log_warning("OpenAI API key not configured")
    ^^^^^^^^^^^
NameError: name 'log_warning' is not defined
2025-08-13 12:52:59,569 - glyphmind.error - ERROR - Reddit API error: 429
2025-08-13 12:53:00,471 - glyphmind.error - ERROR - Reddit API error: 429
2025-08-13 12:53:00,472 - glyphmind.error - ERROR - Reddit API error: 429
2025-08-13 12:53:00,495 - glyphmind.error - ERROR - Reddit API error: 429
2025-08-13 12:53:01,474 - glyphmind.error - ERROR - Reddit API error: 429
2025-08-13 12:53:02,511 - glyphmind.error - ERROR - Reddit API error: 429
2025-08-13 12:53:02,610 - glyphmind.error - ERROR - Reddit API error: 429
2025-08-13 12:53:02,651 - glyphmind.error - ERROR - Reddit API error: 429
2025-08-13 12:53:03,492 - glyphmind.error - ERROR - Reddit API error: 429
2025-08-13 12:53:04,487 - glyphmind.error - ERROR - Reddit API error: 429
2025-08-13 12:53:04,492 - glyphmind.error - ERROR - Reddit API error: 429
2025-08-13 12:53:04,496 - glyphmind.error - ERROR - Reddit API error: 429
2025-08-13 12:53:05,577 - glyphmind.error - ERROR - Reddit API error: 429
2025-08-13 12:53:06,688 - glyphmind.error - ERROR - Reddit API error: 429
2025-08-13 12:53:06,690 - glyphmind.error - ERROR - Reddit API error: 429
2025-08-13 12:53:16,947 - glyphmind.error - ERROR - Failed to initialize OpenAI model | Exception: name 'log_warning' is not defined
Traceback (most recent call last):
  File "C:\Users\Public\ALL WORKING MODELS HERE\NEW MODEL FOR DEV\GLYPHMIND\glyphmind\core\ai_engine.py", line 160, in initialize
    log_warning("OpenAI API key not configured")
    ^^^^^^^^^^^
NameError: name 'log_warning' is not defined
2025-08-13 12:53:17,417 - glyphmind.error - ERROR - Reddit API error: 429
2025-08-13 12:53:18,377 - glyphmind.error - ERROR - Reddit API error: 429
2025-08-13 12:53:18,378 - glyphmind.error - ERROR - Reddit API error: 429
2025-08-13 12:53:18,570 - glyphmind.error - ERROR - Reddit API error: 429
2025-08-13 12:53:19,374 - glyphmind.error - ERROR - Reddit API error: 429
2025-08-13 12:53:20,309 - glyphmind.error - ERROR - Reddit API error: 429
2025-08-13 12:53:20,310 - glyphmind.error - ERROR - Reddit API error: 429
2025-08-13 12:53:20,315 - glyphmind.error - ERROR - Reddit API error: 429
2025-08-13 12:53:21,405 - glyphmind.error - ERROR - Reddit API error: 429
2025-08-13 12:53:22,418 - glyphmind.error - ERROR - Reddit API error: 429
2025-08-13 12:53:22,597 - glyphmind.error - ERROR - Reddit API error: 429
2025-08-13 12:53:22,873 - glyphmind.error - ERROR - Reddit API error: 429
2025-08-13 12:53:23,405 - glyphmind.error - ERROR - Reddit API error: 429
2025-08-13 12:53:24,370 - glyphmind.error - ERROR - Reddit API error: 429
2025-08-13 12:53:24,371 - glyphmind.error - ERROR - Reddit API error: 429
2025-08-13 12:53:29,655 - glyphmind.error - ERROR - Request routing failed | Data: {"request_id": "ed08d984-7a0e-4474-8061-cbb32a6bde6b", "request_type": "status"} | Exception: No route found for request type: RequestType.STATUS
Traceback (most recent call last):
  File "C:\Users\Public\ALL WORKING MODELS HERE\NEW MODEL FOR DEV\GLYPHMIND\glyphmind\router\request_router.py", line 318, in route_request
    raise ValueError(f"No route found for request type: {context.request_type}")
ValueError: No route found for request type: RequestType.STATUS
2025-08-13 12:53:29,655 - glyphmind.error - ERROR - Router error, falling back to direct handler: No route found for request type: RequestType.STATUS
2025-08-13 12:53:31,347 - glyphmind.error - ERROR - Request routing failed | Data: {"request_id": "1cd3f75a-7958-4d73-a214-bb11f33e86a4", "request_type": "status"} | Exception: No route found for request type: RequestType.STATUS
Traceback (most recent call last):
  File "C:\Users\Public\ALL WORKING MODELS HERE\NEW MODEL FOR DEV\GLYPHMIND\glyphmind\router\request_router.py", line 318, in route_request
    raise ValueError(f"No route found for request type: {context.request_type}")
ValueError: No route found for request type: RequestType.STATUS
2025-08-13 12:53:31,348 - glyphmind.error - ERROR - Router error, falling back to direct handler: No route found for request type: RequestType.STATUS
2025-08-13 12:53:35,524 - glyphmind.error - ERROR - Request routing failed | Data: {"request_id": "94fa86b1-adce-4ec0-97d7-bcf438113b05", "request_type": "chat"} | Exception: No route found for request type: RequestType.CHAT
Traceback (most recent call last):
  File "C:\Users\Public\ALL WORKING MODELS HERE\NEW MODEL FOR DEV\GLYPHMIND\glyphmind\router\request_router.py", line 318, in route_request
    raise ValueError(f"No route found for request type: {context.request_type}")
ValueError: No route found for request type: RequestType.CHAT
2025-08-13 12:53:35,524 - glyphmind.error - ERROR - Router error, falling back to direct handler: No route found for request type: RequestType.CHAT
2025-08-13 12:53:48,996 - glyphmind.error - ERROR - Request routing failed | Data: {"request_id": "854e0f02-0474-4381-bb83-a4fcddbd1453", "request_type": "chat"} | Exception: No route found for request type: RequestType.CHAT
Traceback (most recent call last):
  File "C:\Users\Public\ALL WORKING MODELS HERE\NEW MODEL FOR DEV\GLYPHMIND\glyphmind\router\request_router.py", line 318, in route_request
    raise ValueError(f"No route found for request type: {context.request_type}")
ValueError: No route found for request type: RequestType.CHAT
2025-08-13 12:53:48,996 - glyphmind.error - ERROR - Router error, falling back to direct handler: No route found for request type: RequestType.CHAT
2025-08-13 12:53:49,446 - glyphmind.error - ERROR - Reddit API error: 429
2025-08-13 12:54:02,985 - glyphmind.error - ERROR - Request routing failed | Data: {"request_id": "29bcd642-908d-47e1-8fee-3d855c630434", "request_type": "chat"} | Exception: No route found for request type: RequestType.CHAT
Traceback (most recent call last):
  File "C:\Users\Public\ALL WORKING MODELS HERE\NEW MODEL FOR DEV\GLYPHMIND\glyphmind\router\request_router.py", line 318, in route_request
    raise ValueError(f"No route found for request type: {context.request_type}")
ValueError: No route found for request type: RequestType.CHAT
2025-08-13 12:54:02,986 - glyphmind.error - ERROR - Router error, falling back to direct handler: No route found for request type: RequestType.CHAT
2025-08-13 12:54:09,881 - glyphmind.error - ERROR - Request routing failed | Data: {"request_id": "c1635d1c-3b22-4829-8629-dde2e99d405d", "request_type": "chat"} | Exception: No route found for request type: RequestType.CHAT
Traceback (most recent call last):
  File "C:\Users\Public\ALL WORKING MODELS HERE\NEW MODEL FOR DEV\GLYPHMIND\glyphmind\router\request_router.py", line 318, in route_request
    raise ValueError(f"No route found for request type: {context.request_type}")
ValueError: No route found for request type: RequestType.CHAT
2025-08-13 12:54:09,882 - glyphmind.error - ERROR - Router error, falling back to direct handler: No route found for request type: RequestType.CHAT
2025-08-13 12:54:26,917 - glyphmind.error - ERROR - Request routing failed | Data: {"request_id": "8eb98612-f207-43c6-868b-18f6212edc9f", "request_type": "search"} | Exception: No route found for request type: RequestType.SEARCH
Traceback (most recent call last):
  File "C:\Users\Public\ALL WORKING MODELS HERE\NEW MODEL FOR DEV\GLYPHMIND\glyphmind\router\request_router.py", line 318, in route_request
    raise ValueError(f"No route found for request type: {context.request_type}")
ValueError: No route found for request type: RequestType.SEARCH
2025-08-13 12:54:26,917 - glyphmind.error - ERROR - Search endpoint error | Exception: No route found for request type: RequestType.SEARCH
Traceback (most recent call last):
  File "C:\Users\Public\ALL WORKING MODELS HERE\NEW MODEL FOR DEV\GLYPHMIND\glyphmind\server\app.py", line 480, in search_endpoint
    response = await request_router.route_request(context)
               ^^^^^^^^^^^^^^^^^^^^^^^^^^^^^^^^^^^^^^^^^^^
  File "C:\Users\Public\ALL WORKING MODELS HERE\NEW MODEL FOR DEV\GLYPHMIND\glyphmind\router\request_router.py", line 318, in route_request
    raise ValueError(f"No route found for request type: {context.request_type}")
ValueError: No route found for request type: RequestType.SEARCH
